<?xml version="1.0"?>
<robot name="myfirst">
<!-- our circular base -->
  <link name="base_link">
    <visual>
      <geometry>
        <cylinder length="0.3" radius="0.5"/>
      </geometry>
	   <origin rpy="0 0 0" xyz="0 0 0.5"/>
    </visual>
    <collision>
      <geometry>
        <cylinder length="0.3" radius="0.5"/>
      </geometry>
    </collision>
    <inertial>
      <mass value="10"/>
      <inertia ixx="0.4" ixy="0.0" ixz="0.0" iyy="0.4" iyz="0.0" izz="0.2"/>
    </inertial>
</link>


<!--ourleft visuial joint-->
<link name="left_bo2la">
    <visual>
      <geometry>
        <cylinder length="0.3" radius="0.1"/>
      </geometry>
    </visual>
<collision>
      <geometry>
        <cylinder length="0.3" radius="0.1"/>
      </geometry>
</collision>
<inertial>
      <mass value="10"/>
      <inertia ixx="0.4" ixy="0.0" ixz="0.0" iyy="0.4" iyz="0.0" izz="0.2"/>
</inertial>
  </link>

<joint name="base_to_left_bo2la" type="fixed">
<origin rpy="0 0 0" xyz="0 0.6 0.5"/>
    <parent link="base_link"/>
    <child link="left_bo2la"/>
  </joint>

<!--our left leg-->
<link name="left_leg">
    <visual>
      <geometry>
        <box size="0.1 0.6 0.3" />
      </geometry>
      <origin rpy="0 0 0" xyz="0 0.3 0"/>
    </visual>
<collision>
      <geometry>
        <box size="0.1 0.6 0.3"/>
      </geometry>
</collision>
<inertial>
      <mass value="10"/>
      <inertia ixx="0.4" ixy="0.0" ixz="0.0" iyy="0.4" iyz="0.0" izz="0.2"/>
</inertial>
  </link>

<joint name="left_bo2la_to_left_leg" type="continuous">
<origin rpy="0 0 0" xyz="0 0 0"/>
    <parent link="left_bo2la"/>
    <child link="left_leg"/>
    <axis xyz="0 0 1"/>
  </joint>

<!--our left_bo2la_2-->
<link name="left_bo2la_2">
    <visual>
      <geometry>
        <cylinder length="0.3" radius="0.1"/>
      </geometry>
      <origin rpy="0 1.57075 0" xyz="0 0 0"/>
    </visual>
<collision>
      <geometry>
        <cylinder length="0.3" radius="0.1"/>
      </geometry>
</collision>
<inertial>
      <mass value="10"/>
      <inertia ixx="0.4" ixy="0.0" ixz="0.0" iyy="0.4" iyz="0.0" izz="0.2"/>
</inertial>
  </link>

<joint name="left_leg_to_left_bo2la_2" type="fixed">
<origin rpy="0 0 0" xyz="0 0.6 0"/>
    <parent link="left_leg"/>
    <child link="left_bo2la_2"/>
  </joint>

<!--our left leg_2-->
<link name="left_leg_2">
    <visual>
      <geometry>
        <box size="0.1 0.4 0.1" />
      </geometry>
      <origin rpy="1.57075 0 0" xyz="0 0 -0.2"/>
    </visual>
<collision>
      <geometry>
        <box size="0.1 0.4 0.1"/>
      </geometry>
</collision>
<inertial>
      <mass value="10"/>
      <inertia ixx="0.4" ixy="0.0" ixz="0.0" iyy="0.4" iyz="0.0" izz="0.2"/>
</inertial>
  </link>

<joint name="left_bo2la_2_to_left_leg" type="continuous">
<origin rpy="0 0 0" xyz="0 0 0"/>
    <parent link="left_bo2la_2"/>
    <child link="left_leg_2"/>
  </joint>


<!--our right visuial joint-->
<link name="right_bo2la">
    <visual>
      <geometry>
        <cylinder length="0.3" radius="0.1"/>
      </geometry>
    </visual>
<collision>
      <geometry>
        <cylinder length="0.3" radius="0.1"/>
      </geometry>
</collision>
<inertial>
      <mass value="10"/>
      <inertia ixx="0.4" ixy="0.0" ixz="0.0" iyy="0.4" iyz="0.0" izz="0.2"/>
</inertial>
  </link>

<joint name="base_to_right_bo2la" type="fixed">
<origin rpy="0 0 0" xyz="0 -0.6 0.5"/>
    <parent link="base_link"/>
    <child link="right_bo2la"/>
  </joint>

<!--our right leg-->
<link name="right_leg">
    <visual>
      <geometry>
        <box size="0.1 0.6 0.3" />
      </geometry>
    <origin rpy="0 0 0" xyz="0 -0.3 0"/>
    </visual>
<collision>
      <geometry>
        <box size="0.1 0.6 0.3"/>
      </geometry>
</collision>
<inertial>
      <mass value="10"/>
      <inertia ixx="0.4" ixy="0.0" ixz="0.0" iyy="0.4" iyz="0.0" izz="0.2"/>
</inertial>
  </link>

<joint name="right_bo2la_to_right_leg" type="continuous">
<origin rpy="0 0 0" xyz="0 0 0"/>
    <parent link="right_bo2la"/>
    <child link="right_leg"/>
    <axis xyz="0 0 1"/>
  </joint>

<!--our right_bo2la_2-->
<link name="right_bo2la_2">
    <visual>
      <geometry>
        <cylinder length="0.3" radius="0.1"/>
      </geometry>
      <origin rpy="0 1.57075 0" xyz="0 0 0"/>
    </visual>
<collision>
      <geometry>
        <cylinder length="0.3" radius="0.1"/>
      </geometry>
</collision>
<inertial>
      <mass value="10"/>
      <inertia ixx="0.4" ixy="0.0" ixz="0.0" iyy="0.4" iyz="0.0" izz="0.2"/>
</inertial>
  </link>

<joint name="right_leg_to_right_bo2la_2" type="fixed">
<origin rpy="0 0 0" xyz="0 -0.6 0"/>
    <parent link="right_leg"/>
    <child link="right_bo2la_2"/>
  </joint>

<!--our right leg_2-->
<link name="right_leg_2">
    <visual>
      <geometry>
        <box size="0.1 0.4 0.1" />
      </geometry>
      <origin rpy="1.57075 0 0" xyz="0 0 -0.2"/>
    </visual>
<collision>
      <geometry>
        <box size="0.1 0.4 0.1"/>
      </geometry>
</collision>
<inertial>
      <mass value="10"/>
      <inertia ixx="0.4" ixy="0.0" ixz="0.0" iyy="0.4" iyz="0.0" izz="0.2"/>
</inertial>
  </link>

<joint name="right_bo2la_2_to_right_leg_2" type="continuous">
<origin rpy="0 0 0" xyz="0 0 0"/>
    <parent link="right_bo2la_2"/>
    <child link="right_leg_2"/>
  </joint>


<!--our front visuial joint-->
<link name="front_bo2la">
    <visual>
      <geometry>
        <cylinder length="0.3" radius="0.1"/>
      </geometry>
    </visual>
<collision>
      <geometry>
        <cylinder length="0.3" radius="0.1"/>
      </geometry>
</collision>
<inertial>
      <mass value="10"/>
      <inertia ixx="0.4" ixy="0.0" ixz="0.0" iyy="0.4" iyz="0.0" izz="0.2"/>
</inertial>
  </link>

<joint name="base_to_front_bo2la" type="fixed">
<origin rpy="0 0 0" xyz="0.6 0 0.5"/>
    <parent link="base_link"/>
    <child link="front_bo2la"/>
  </joint>

<!--our front leg-->
<link name="front_leg">
    <visual>
      <geometry>
        <box size="0.1 0.6 0.3" />
      </geometry>
      <origin rpy="0 0 1.57075" xyz="0.3 0 0"/>
    </visual>
<collision>
      <geometry>
        <box size="0.1 0.6 0.3"/>
      </geometry>
</collision>
<inertial>
      <mass value="10"/>
      <inertia ixx="0.4" ixy="0.0" ixz="0.0" iyy="0.4" iyz="0.0" izz="0.2"/>
</inertial>
  </link>

<joint name="front_bo2la_to_front_leg" type="continuous">
<origin rpy="0 0 0" xyz="0 0 0"/>
    <parent link="front_bo2la"/>
    <child link="front_leg"/>
    <axis xyz="0 0 1"/>
  </joint>

<!--our front_bo2la_2-->
<link name="front_bo2la_2">
    <visual>
      <geometry>
        <cylinder length="0.3" radius="0.1"/>
      </geometry>
      <origin rpy="1.57075 0 0" xyz="0 0 0"/>
    </visual>
<collision>
      <geometry>
        <cylinder length="0.3" radius="0.1"/>
      </geometry>
</collision>
<inertial>
      <mass value="10"/>
      <inertia ixx="0.4" ixy="0.0" ixz="0.0" iyy="0.4" iyz="0.0" izz="0.2"/>
</inertial>
  </link>

<joint name="front_leg_to_front_bo2la_2" type="fixed">
<origin rpy="0 0 0" xyz="0.6 0 0"/>
    <parent link="front_leg"/>
    <child link="front_bo2la_2"/>
  </joint>

<!--our front leg_2-->
<link name="front_leg_2">
    <visual>
      <geometry>
        <box size="0.1 0.4 0.1" />
      </geometry>
      <origin rpy="1.57075 0 0" xyz="0 0 -0.2"/>
    </visual>
<collision>
      <geometry>
        <box size="0.1 0.4 0.1"/>
      </geometry>
</collision>
<inertial>
      <mass value="10"/>
      <inertia ixx="0.4" ixy="0.0" ixz="0.0" iyy="0.4" iyz="0.0" izz="0.2"/>
</inertial>
  </link>

<joint name="front_bo2la_2_to_front_leg_2" type="continuous">
<origin rpy="0 0 0" xyz="0 0 0"/>
    <parent link="front_bo2la_2"/>
    <child link="front_leg_2"/>
    <axis xyz="0 1 0"/>

  </joint>


<!--our back visuial joint-->
<link name="back_bo2la">
    <visual>
      <geometry>
        <cylinder length="0.3" radius="0.1"/>
      </geometry>
    </visual>
<collision>
      <geometry>
        <cylinder length="0.3" radius="0.1"/>
      </geometry>
</collision>
<inertial>
      <mass value="10"/>
      <inertia ixx="0.4" ixy="0.0" ixz="0.0" iyy="0.4" iyz="0.0" izz="0.2"/>
</inertial>
  </link>

<joint name="base_to_back_bo2la" type="fixed">
<origin rpy="0 0 0" xyz="-0.6 0 0.5"/>
    <parent link="base_link"/>
    <child link="back_bo2la"/>
  </joint>

<!--our back leg-->
<link name="back_leg">
    <visual>
      <geometry>
        <box size="0.1 0.6 0.3" />
      </geometry>
      <origin rpy="0 0 1.57075" xyz="-0.3 0 0"/>
    </visual>
<collision>
      <geometry>
        <box size="0.1 0.6 0.3"/>
      </geometry>
</collision>
<inertial>
      <mass value="10"/>
      <inertia ixx="0.4" ixy="0.0" ixz="0.0" iyy="0.4" iyz="0.0" izz="0.2"/>
</inertial>
  </link>

<joint name="back_bo2la_to_back_leg" type="continuous">
<origin rpy="0 0 0" xyz="0 0 0"/>
    <parent link="back_bo2la"/>
    <child link="back_leg"/>
    <axis xyz="0 0 1"/>
  </joint>

<!--our back_bo2la_2-->
<link name="back_bo2la_2">
    <visual>
      <geometry>
        <cylinder length="0.3" radius="0.1"/>
      </geometry>
      <origin rpy="1.57075 0 0" xyz="0 0 0"/>
    </visual>
<collision>
      <geometry>
        <cylinder length="0.3" radius="0.1"/>
      </geometry>
</collision>
<inertial>
      <mass value="10"/>
      <inertia ixx="0.4" ixy="0.0" ixz="0.0" iyy="0.4" iyz="0.0" izz="0.2"/>
</inertial>
  </link>

<joint name="back_leg_to_back_bo2la_2" type="fixed">
<origin rpy="0 0 0" xyz="-0.6 0 0"/>
    <parent link="back_leg"/>
    <child link="back_bo2la_2"/>
  </joint>

<!--back_leg_2-->
<link name="back_leg_2">
    <visual>
      <geometry>
        <box size="0.1 0.4 0.1" />
      </geometry>
      <origin rpy="1.57075 0 0" xyz="0 0 -0.2"/>
    </visual>
<collision>
      <geometry>
        <box size="0.1 0.4 0.1"/>
      </geometry>
</collision>
<inertial>
      <mass value="10"/>
      <inertia ixx="0.4" ixy="0.0" ixz="0.0" iyy="0.4" iyz="0.0" izz="0.2"/>
</inertial>
  </link>

<joint name="back_bo2la_2_to_back_leg_2" type="continuous">
<origin rpy="0 0 0" xyz="0 0 0"/>
    <parent link="back_bo2la_2"/>
    <child link="back_leg_2"/>
    <axis xyz="0 1 0"/>

  </joint>

<gazebo reference="base_link">
  <material>Gazebo/Red</material>
</gazebo>
<gazebo reference="left_bo2la">
  <material>Gazebo/Blue</material>
</gazebo>
<gazebo reference="right_bo2la">
  <material>Gazebo/Blue</material>
</gazebo>
<gazebo reference="front_bo2la">
  <material>Gazebo/Blue</material>
</gazebo>
<gazebo reference="back_bo2la">
  <material>Gazebo/Blue</material>
</gazebo>
<gazebo reference="front_leg">
  <material>Gazebo/Red</material>
</gazebo>
<gazebo reference="back_leg">
  <material>Gazebo/Red</material>
</gazebo>
<gazebo reference="left_leg">
  <material>Gazebo/Red</material>
</gazebo>
<gazebo reference="right_leg">
  <material>Gazebo/Red</material>
</gazebo>
<gazebo reference="front_bo2la_2">
  <material>Gazebo/Blue</material>
</gazebo>
<gazebo reference="back_bo2la_2">
  <material>Gazebo/Blue</material>
</gazebo>
<gazebo reference="left_bo2la_2">
  <material>Gazebo/Blue</material>
</gazebo>
<gazebo reference="right_bo2la_2">
  <material>Gazebo/Blue</material>
</gazebo>
<gazebo reference="front_leg_2">
  <material>Gazebo/Red</material>
</gazebo>
<gazebo reference="back_leg_2">
  <material>Gazebo/Red</material>
</gazebo>
<gazebo reference="left_leg_2">
  <material>Gazebo/Red</material>
</gazebo>
<gazebo reference="right_leg_2">
  <material>Gazebo/Red</material>
</gazebo>
<transmission name="tran1">
    <type>transmission_interface/SimpleTransmission</type>
    <joint name="left_bo2la_to_left_leg">
      <hardwareInterface>hardware_interface/EffortJointInterface</hardwareInterface>
    </joint>
    <actuator name="motor1">
      <hardwareInterface>hardware_interface/EffortJointInterface</hardwareInterface>
      <mechanicalReduction>1</mechanicalReduction>
    </actuator>
  </transmission>

  <gazebo>
   <plugin name="gazebo_ros_control" filename="libgazebo_ros_control.so">
     <robotNamespace>/rrbot</robotNamespace>
   </plugin>
 </gazebo>

</robot>
